Workbook

Sheet PLANGRID
A1: ID | B1: FLATS | C1: Task # | D1: Stamp | E1: Title | F1: Description | G1: Date | H1: Status | I1: Type | J1: Sheet | K1: Location | L1: Root Cause | M1: Created By | N1: Assigned To | O1: Watchers | P1: # Photos | Q1: Color | R1: Archived | S1: Start Date | T1: Due Date | U1: Cost Impact | V1: Cost Impact Amount | W1: Schedule Impact | X1: Schedule Impact Amount (days) | Y1: List | Z1: Last Updated | AA1: Closed On
A2: =B2&D2 -> 1905F3 | B2: =LEFT($J:$J,4) -> 1905 | C2: 23871 | D2: F3 | E2: F3 FAS Integration IR | G2: Jun 01, 2026 @ 16:53 | H2: closed | I2: Issue | J2: 1905_Main 1 Sub B C D E F | M2: vivek.muralidharan@sobhaconst.com | P2: 1 | Q2: blue | R2: No | V2: Unspecified | X2: Unspecified | Z2: Jun 09, 2026 @ 09:13 | AA2: Jun 09, 2026 @ 09:13
A3: =B3&D3 -> 3210D4 | B3: =LEFT($J:$J,4) -> 3210 | C3: 23727 | D3: D4 | E3: D4 Intercom IR | F3: Intercom IR | G3: Apr 30, 2026 @ 04:00 | H3: closed | I3: Issue | J3: 3210 _Main 1 Sub B C D E F | K3: 202 | M3: dharmaraja.kalimuthu@sobhaconst.com | P3: 2 | Q3: blue | R3: No | V3: Unspecified | X3: Unspecified | Y3: Sub D - Electrical T&C | Z3: Jul 22, 2026 @ 12:53 | AA3: Jul 22, 2026 @ 12:53
A4: =B4&D4 -> 3210D2 | B4: =LEFT($J:$J,4) -> 3210 | C4: 23726 | D4: D2 | E4: D2 ONU Panel/Data Points IR | F4: ONU Panel/Data Points IR | G4: Apr 30, 2026 @ 04:00 | H4: closed | I4: Issue | J4: 3210 _Main 1 Sub B C D E F | K4: 202 | M4: dharmaraja.kalimuthu@sobhaconst.com | P4: 2 | Q4: blue | R4: No | V4: Unspecified | X4: Unspecified | Y4: Sub D - Electrical T&C | Z4: Jul 22, 2026 @ 12:53 | AA4: Jul 22, 2026 @ 12:53
A5: =B5&D5 -> 3109C2 | B5: =LEFT($J:$J,4) -> 3109 | C5: 23713 | D5: C2 | E5: C2 Gas Detector/FAS Integration IR | F5: Gas Detector/FAS Integration IR | G5: Apr 30, 2026 @ 04:00 | H5: closed | I5: Planned Work | J5: 3109 _Main 1 Sub B C D E F | M5: dharmaraja.kalimuthu@sobhaconst.com | P5: 3 | Q5: blue | R5: No | V5: Unspecified | X5: Unspecified | Y5: Sub C - LPG T&C | Z5: Jul 20, 2026 @ 17:49 | AA5: Jul 20, 2026 @ 17:49
A6: =B6&D6 -> 3109F3 | B6: =LEFT($J:$J,4) -> 3109 | C6: 23699 | D6: F3 | E6: F3 FAS Integration IR | F6: FAS Integration IR | G6: Apr 30, 2026 @ 04:00 | H6: closed | I6: Planned Work | J6: 3109 _Main 1 Sub B C D E F | M6: dharmaraja.kalimuthu@sobhaconst.com | P6: 1 | Q6: blue | R6: No | V6: Unspecified | X6: Unspecified | Y6: Sub F - Fire Fighting T&C | Z6: Jun 24, 2026 @ 12:27 | AA6: Jun 24, 2026 @ 12:27
A7: =B7&D7 -> 3109F2 | B7: =LEFT($J:$J,4) -> 3109 | C7: 23697 | D7: F2 | E7: F2 Heat/Smoke Detector IR | F7: Heat/Smoke Detector IR | G7: Apr 30, 2026 @ 04:00 | H7: closed | I7: Planned Work | J7: 3109 _Main 1 Sub B C D E F | M7: dharmaraja.kalimuthu@sobhaconst.com | P7: 6 | Q7: blue | R7: No | V7: Unspecified | X7: Unspecified | Y7: Sub F - Fire Fighting T&C | Z7: Jun 24, 2026 @ 12:27 | AA7: Jun 24, 2026 @ 12:27
A8: =B8&D8 -> 1204C2 | B8: =LEFT($J:$J,4) -> 1204 | C8: 23420 | D8: C2 | E8: C2 Gas Detector/FAS Integration IR | G8: May 01, 2026 @ 17:13 | H8: closed | I8: Planned Work | J8: 1204_Main 1 Sub B C D E F | M8: abishek.govindan@sobhaconst.com | P8: 3 | Q8: blue | R8: No | V8: Unspecified | X8: Unspecified | Y8: Sub C - LPG T&C | Z8: May 03, 2026 @ 09:50 | AA8: May 03, 2026 @ 09:50
A9: =B9&D9 -> 2002F3 | B9: =LEFT($J:$J,4) -> 2002 | C9: 23417 | D9: F3 | E9: F3 FAS Integration IR | G9: May 01, 2026 @ 15:40 | H9: closed | I9: Issue | J9: 2002_Main 1 Sub B C D E F | M9: mohammad.mujiburrahman@sobhaconst.com | P9: 1 | Q9: blue | R9: No | V9: Unspecified | X9: Unspecified | Z9: Jul 17, 2026 @ 16:07 | AA9: Jul 17, 2026 @ 16:07
A10: =B10&D10 -> 2002F2 | B10: =LEFT($J:$J,4) -> 2002 | C10: 23416 | D10: F2 | E10: F2 Heat/Smoke Detector IR | G10: May 01, 2026 @ 15:40 | H10: closed | I10: Issue | J10: 2002_Main 1 Sub B C D E F | M10: mohammad.mujiburrahman@sobhaconst.com | P10: 9 | Q10: blue | R10: No | V10: Unspecified | X10: Unspecified | Z10: Jul 21, 2026 @ 15:54 | AA10: Jul 21, 2026 @ 15:54
A11: =B11&D11 -> 2002D7 | B11: =LEFT($J:$J,4) -> 2002 | C11: 23412 | D11: D7 | E11: D7 Booster IR | G11: May 01, 2026 @ 15:40 | H11: closed | I11: Issue | J11: 2002_Main 1 Sub B C D E F | M11: mohammad.mujiburrahman@sobhaconst.com | P11: 1 | Q11: blue | R11: No | V11: Unspecified | X11: Unspecified | Z11: Jun 02, 2026 @ 12:15 | AA11: Jun 02, 2026 @ 12:15
A12: =B12&D12 -> 2002D4 | B12: =LEFT($J:$J,4) -> 2002 | C12: 23409 | D12: D4 | E12: D4 Intercom IR | G12: May 01, 2026 @ 15:39 | H12: closed | I12: Issue | J12: 2002_Main 1 Sub B C D E F | M12: mohammad.mujiburrahman@sobhaconst.com | P12: 2 | Q12: blue | R12: No | V12: Unspecified | X12: Unspecified | Z12: Jul 27, 2026 @ 09:17 | AA12: Jul 27, 2026 @ 09:17
A13: =B13&D13 -> 2002D2 | B13: =LEFT($J:$J,4) -> 2002 | C13: 23407 | D13: D2 | E13: D2 ONU Panel/Data Points IR | G13: May 01, 2026 @ 15:39 | H13: closed | I13: Issue | J13: 2002_Main 1 Sub B C D E F | M13: mohammad.mujiburrahman@sobhaconst.com | P13: 2 | Q13: blue | R13: No | V13: Unspecified | X13: Unspecified | Z13: Jul 22, 2026 @ 17:52 | AA13: Jul 22, 2026 @ 17:52
A14: =B14&D14 -> 2002C2 | B14: =LEFT($J:$J,4) -> 2002 | C14: 23404 | D14: C2 | E14: C2 Gas Detector/FAS Integration IR | G14: May 01, 2026 @ 15:39 | H14: closed | I14: Issue | J14: 2002_Main 1 Sub B C D E F | M14: mohammad.mujiburrahman@sobhaconst.com | P14: 3 | Q14: blue | R14: No | V14: Unspecified | X14: Unspecified | Z14: Jul 22, 2026 @ 17:53 | AA14: Jul 22, 2026 @ 17:53
A15: =B15&D15 -> 1909C2 | B15: =LEFT($J:$J,4) -> 1909 | C15: 16951 | D15: C2 | E15: C2 Gas Detector/FAS Integration IR | F15: Gas Detector/FAS Integration IR | G15: Jan 09, 2026 @ 04:00 | H15: closed | I15: Planned Work | J15: 1909_Main 1 Sub B C D E F | M15: sathvik@sobhaconst.com | P15: 3 | Q15: blue | R15: No | V15: Unspecified | X15: Unspecified | Y15: Sub C - LPG T&C | Z15: Jun 02, 2026 @ 15:21 | AA15: Jun 02, 2026 @ 15:21
A16: =B16&D16 -> 1909F2 | B16: =LEFT($J:$J,4) -> 1909 | C16: 16946 | D16: F2 | E16: F2 Heat/Smoke Detector IR | F16: Heat/Smoke Detector IR | G16: Jan 09, 2026 @ 04:00 | H16: closed | I16: Planned Work | J16: 1909_Main 1 Sub B C D E F | M16: sathvik@sobhaconst.com | P16: 6 | Q16: blue | R16: No | V16: Unspecified | X16: Unspecified | Y16: Sub F - Fire Fighting T&C | Z16: May 12, 2026 @ 17:57 | AA16: May 12, 2026 @ 17:57
A17: =B17&D17 -> 1909D7 | B17: =LEFT($J:$J,4) -> 1909 | C17: 16944 | D17: D7 | E17: D7 Booster IR | F17: Booster IR | G17: Jan 09, 2026 @ 04:00 | H17: closed | I17: Planned Work | J17: 1909_Main 1 Sub B C D E F | M17: sathvik@sobhaconst.com | P17: 1 | Q17: blue | R17: No | V17: Unspecified | X17: Unspecified | Y17: Sub D - Electrical T&C | Z17: May 12, 2026 @ 13:40 | AA17: May 12, 2026 @ 13:40
A18: =B18&D18 -> 1909D4 | B18: =LEFT($J:$J,4) -> 1909 | C18: 16942 | D18: D4 | E18: D4 Intercom IR | F18: Intercom IR | G18: Jan 09, 2026 @ 04:00 | H18: closed | I18: Planned Work | J18: 1909_Main 1 Sub B C D E F | M18: sathvik@sobhaconst.com | P18: 2 | Q18: blue | R18: No | V18: Unspecified | X18: Unspecified | Y18: Sub D - Electrical T&C | Z18: Jun 03, 2026 @ 15:34 | AA18: Jun 03, 2026 @ 15:34
A19: =B19&D19 -> 1909F3 | B19: =LEFT($J:$J,4) -> 1909 | C19: 16939 | D19: F3 | E19: F3 FAS Integration IR | F19: FAS Integration IR | G19: Jan 09, 2026 @ 04:00 | H19: closed | I19: Planned Work | J19: 1909_Main 1 Sub B C D E F | M19: sathvik@sobhaconst.com | P19: 1 | Q19: blue | R19: No | V19: Unspecified | X19: Unspecified | Y19: Sub F - Fire Fighting T&C | Z19: May 12, 2026 @ 17:59 | AA19: May 12, 2026 @ 17:58
A20: =B20&D20 -> 1909D2 | B20: =LEFT($J:$J,4) -> 1909 | C20: 16931 | D20: D2 | E20: D2 ONU Panel/Data Points IR | F20: ONU Panel/Data Points IR | G20: Jan 09, 2026 @ 04:00 | H20: closed | I20: Planned Work | J20: 1909_Main 1 Sub B C D E F | M20: sathvik@sobhaconst.com | P20: 2 | Q20: blue | R20: No | V20: Unspecified | X20: Unspecified | Y20: Sub D - Electrical T&C | Z20: Jun 03, 2026 @ 15:24 | AA20: Jun 03, 2026 @ 15:24
A21: =B21&D21 -> 1309C2 | B21: =LEFT($J:$J,4) -> 1309 | C21: 16922 | D21: C2 | E21: C2 Gas Detector/FAS Integration IR | F21: Gas Detector/FAS Integration IR | G21: Jan 09, 2026 @ 04:00 | H21: closed | I21: Planned Work | J21: 1309_Main 1 Sub B C D E F | M21: sathvik@sobhaconst.com | P21: 3 | Q21: blue | R21: No | V21: Unspecified | X21: Unspecified | Y21: Sub C - LPG T&C | Z21: Jun 04, 2026 @ 17:05 | AA21: Jun 04, 2026 @ 17:05
A22: =B22&D22 -> 1309F2 | B22: =LEFT($J:$J,4) -> 1309 | C22: 16917 | D22: F2 | E22: F2 Heat/Smoke Detector IR | F22: Heat/Smoke Detector IR | G22: Jan 09, 2026 @ 04:00 | H22: closed | I22: Planned Work | J22: 1309_Main 1 Sub B C D E F | K22: 1309 | M22: sathvik@sobhaconst.com | P22: 6 | Q22: blue | R22: No | V22: Unspecified | X22: Unspecified | Y22: Sub F - Fire Fighting T&C | Z22: Apr 23, 2026 @ 12:41 | AA22: Apr 23, 2026 @ 12:41
A23: =B23&D23 -> 1309D7 | B23: =LEFT($J:$J,4) -> 1309 | C23: 16915 | D23: D7 | E23: D7 Booster IR | F23: Booster IR | G23: Jan 09, 2026 @ 04:00 | H23: closed | I23: Planned Work | J23: 1309_Main 1 Sub B C D E F | M23: sathvik@sobhaconst.com | P23: 1 | Q23: blue | R23: No | V23: Unspecified | X23: Unspecified | Y23: Sub D - Electrical T&C | Z23: Apr 22, 2026 @ 18:10 | AA23: Apr 22, 2026 @ 18:10
A24: =B24&D24 -> 1309D4 | B24: =LEFT($J:$J,4) -> 1309 | C24: 16913 | D24: D4 | E24: D4 Intercom IR | F24: Intercom IR | G24: Jan 09, 2026 @ 04:00 | H24: closed | I24: Planned Work | J24: 1309_Main 1 Sub B C D E F | K24: 202 | M24: sathvik@sobhaconst.com | P24: 2 | Q24: blue | R24: No | V24: Unspecified | X24: Unspecified | Y24: Sub D - Electrical T&C | Z24: May 11, 2026 @ 12:10 | AA24: May 11, 2026 @ 12:10
A25: =B25&D25 -> 1309F3 | B25: =LEFT($J:$J,4) -> 1309 | C25: 16910 | D25: F3 | E25: F3 FAS Integration IR | F25: FAS Integration IR | G25: Jan 09, 2026 @ 04:00 | H25: closed | I25: Planned Work | J25: 1309_Main 1 Sub B C D E F | M25: sathvik@sobhaconst.com | P25: 1 | Q25: blue | R25: No | V25: Unspecified | X25: Unspecified | Y25: Sub F - Fire Fighting T&C | Z25: Apr 23, 2026 @ 12:49 | AA25: Apr 23, 2026 @ 12:49
A26: =B26&D26 -> 1309D2 | B26: =LEFT($J:$J,4) -> 1309 | C26: 16902 | D26: D2 | E26: D2 ONU Panel/Data Points IR | F26: ONU Panel/Data Points IR | G26: Jan 09, 2026 @ 04:00 | H26: closed | I26: Planned Work | J26: 1309_Main 1 Sub B C D E F | M26: sathvik@sobhaconst.com | P26: 2 | Q26: blue | R26: No | V26: Unspecified | X26: Unspecified | Y26: Sub D - Electrical T&C | Z26: May 05, 2026 @ 08:18 | AA26: May 05, 2026 @ 08:18
A27: =B27&D27 -> 3301F2 | B27: =LEFT($J:$J,4) -> 3301 | C27: 16887 | D27: F2 | E27: F2 Heat/Smoke Detector IR | F27: Heat/Smoke Detector IR | G27: Jan 09, 2026 @ 04:00 | H27: closed | I27: Planned Work | J27: 3301_Main 1 Sub B C D E F | M27: sathvik@sobhaconst.com | P27: 8 | Q27: blue | R27: No | V27: Unspecified | X27: Unspecified | Y27: Sub F - Fire Fighting T&C | Z27: Jul 15, 2026 @ 13:13 | AA27: Jul 15, 2026 @ 13:13
A28: =B28&D28 -> 3301D4 | B28: =LEFT($J:$J,4) -> 3301 | C28: 16885 | D28: D4 | E28: D4 Intercom IR | F28: Intercom IR | G28: Jan 09, 2026 @ 04:00 | H28: closed | I28: Planned Work | J28: 3301_Main 1 Sub B C D E F | K28: 202 | M28: sathvik@sobhaconst.com | P28: 2 | Q28: blue | R28: No | V28: Unspecified | X28: Unspecified | Y28: Sub D - Electrical T&C | Z28: Jul 27, 2026 @ 09:17 | AA28: Jul 27, 2026 @ 09:17
A29: =B29&D29 -> 3301D2 | B29: =LEFT($J:$J,4) -> 3301 | C29: 16880 | D29: D2 | E29: D2 ONU Panel/Data Points IR | F29: ONU Panel/Data Points IR | G29: Jan 09, 2026 @ 04:00 | H29: closed | I29: Planned Work | J29: 3301_Main 1 Sub B C D E F | K29: 202 | M29: sathvik@sobhaconst.com | P29: 2 | Q29: blue | R29: No | V29: Unspecified | X29: Unspecified | Y29: Sub D - Electrical T&C | Z29: Jul 27, 2026 @ 17:03 | AA29: Jul 27, 2026 @ 17:03
A30: =B30&D30 -> 3301F3 | B30: =LEFT($J:$J,4) -> 3301 | C30: 16877 | D30: F3 | E30: F3 FAS Integration IR | F30: FAS Integration IR | G30: Jan 09, 2026 @ 04:00 | H30: closed | I30: Planned Work | J30: 3301_Main 1 Sub B C D E F | M30: sathvik@sobhaconst.com | P30: 1 | Q30: blue | R30: No | V30: Unspecified | X30: Unspecified | Y30: Sub F - Fire Fighting T&C | Z30: Jun 24, 2026 @ 12:29 | AA30: Jun 24, 2026 @ 12:29
A31: =B31&D31 -> 3301C2 | B31: =LEFT($J:$J,4) -> 3301 | C31: 16871 | D31: C2 | E31: C2 Gas Detector/FAS Integration IR | F31: Gas Detector/FAS Integration IR | G31: Jan 09, 2026 @ 04:00 | H31: closed | I31: Planned Work | J31: 3301_Main 1 Sub B C D E F | M31: sathvik@sobhaconst.com | P31: 3 | Q31: blue | R31: No | V31: Unspecified | X31: Unspecified | Y31: Sub C - LPG T&C | Z31: Jul 27, 2026 @ 17:03 | AA31: Jul 27, 2026 @ 17:03
A32: =B32&D32 -> 3301D7 | B32: =LEFT($J:$J,4) -> 3301 | C32: 16869 | D32: D7 | E32: D7 Booster IR | F32: Booster IR | G32: Jan 09, 2026 @ 04:00 | H32: closed | I32: Planned Work | J32: 3301_Main 1 Sub B C D E F | M32: sathvik@sobhaconst.com | P32: 1 | Q32: blue | R32: No | V32: Unspecified | X32: Unspecified | Y32: Sub D - Electrical T&C | Z32: Jun 01, 2026 @ 14:03 | AA32: Jun 01, 2026 @ 14:03
A33: =B33&D33 -> 3302F2 | B33: =LEFT($J:$J,4) -> 3302 | C33: 16858 | D33: F2 | E33: F2 Heat/Smoke Detector IR | F33: Heat/Smoke Detector IR | G33: Jan 09, 2026 @ 04:00 | H33: closed | I33: Planned Work | J33: 3302_Main 1 Sub B C D E F | M33: sathvik@sobhaconst.com | P33: 9 | Q33: blue | R33: No | V33: Unspecified | X33: Unspecified | Y33: Sub F - Fire Fighting T&C | Z33: Jul 15, 2026 @ 13:14 | AA33: Jul 15, 2026 @ 13:14
A34: =B34&D34 -> 3302D4 | B34: =LEFT($J:$J,4) -> 3302 | C34: 16856 | D34: D4 | E34: D4 Intercom IR | F34: Intercom IR | G34: Jan 09, 2026 @ 04:00 | H34: closed | I34: Planned Work | J34: 3302_Main 1 Sub B C D E F | K34: 202 | M34: sathvik@sobhaconst.com | P34: 2 | Q34: blue | R34: No | V34: Unspecified | X34: Unspecified | Y34: Sub D - Electrical T&C | Z34: Jul 27, 2026 @ 09:17 | AA34: Jul 27, 2026 @ 09:17
A35: =B35&D35 -> 3302D2 | B35: =LEFT($J:$J,4) -> 3302 | C35: 16851 | D35: D2 | E35: D2 ONU Panel/Data Points IR | F35: ONU Panel/Data Points IR | G35: Jan 09, 2026 @ 04:00 | H35: closed | I35: Planned Work | J35: 3302_Main 1 Sub B C D E F | K35: 202 | M35: sathvik@sobhaconst.com | P35: 2 | Q35: blue | R35: No | V35: Unspecified | X35: Unspecified | Y35: Sub D - Electrical T&C | Z35: Jul 27, 2026 @ 18:16 | AA35: Jul 27, 2026 @ 18:16
A36: =B36&D36 -> 3302F3 | B36: =LEFT($J:$J,4) -> 3302 | C36: 16848 | D36: F3 | E36: F3 FAS Integration IR | F36: FAS Integration IR | G36: Jan 09, 2026 @ 04:00 | H36: closed | I36: Planned Work | J36: 3302_Main 1 Sub B C D E F | M36: sathvik@sobhaconst.com | P36: 1 | Q36: blue | R36: No | V36: Unspecified | X36: Unspecified | Y36: Sub F - Fire Fighting T&C | Z36: Jun 24, 2026 @ 12:30 | AA36: Jun 24, 2026 @ 12:30
A37: =B37&D37 -> 3302C2 | B37: =LEFT($J:$J,4) -> 3302 | C37: 16842 | D37: C2 | E37: C2 Gas Detector/FAS Integration IR | F37: Gas Detector/FAS Integration IR | G37: Jan 09, 2026 @ 04:00 | H37: closed | I37: Planned Work | J37: 3302_Main 1 Sub B C D E F | M37: sathvik@sobhaconst.com | P37: 3 | Q37: blue | R37: No | V37: Unspecified | X37: Unspecified | Y37: Sub C - LPG T&C | Z37: Jul 27, 2026 @ 18:16 | AA37: Jul 27, 2026 @ 18:16
A38: =B38&D38 -> 3302D7 | B38: =LEFT($J:$J,4) -> 3302 | C38: 16840 | D38: D7 | E38: D7 Booster IR | F38: Booster IR | G38: Jan 09, 2026 @ 04:00 | H38: closed | I38: Planned Work | J38: 3302_Main 1 Sub B C D E F | M38: sathvik@sobhaconst.com | P38: 1 | Q38: blue | R38: No | V38: Unspecified | X38: Unspecified | Y38: Sub D - Electrical T&C | Z38: Jun 01, 2026 @ 14:03 | AA38: Jun 01, 2026 @ 14:03
A39: =B39&D39 -> 3303F2 | B39: =LEFT($J:$J,4) -> 3303 | C39: 16829 | D39: F2 | E39: F2 Heat/Smoke Detector IR | F39: Heat/Smoke Detector IR | G39: Jan 09, 2026 @ 04:00 | H39: closed | I39: Planned Work | J39: 3303_Main 1 Sub B C D E F | M39: sathvik@sobhaconst.com | P39: 9 | Q39: blue | R39: No | V39: Unspecified | X39: Unspecified | Y39: Sub F - Fire Fighting T&C | Z39: Jul 17, 2026 @ 14:03 | AA39: Jul 17, 2026 @ 14:03
A40: =B40&D40 -> 3303D4 | B40: =LEFT($J:$J,4) -> 3303 | C40: 16827 | D40: D4 | E40: D4 Intercom IR | F40: Intercom IR | G40: Jan 09, 2026 @ 04:00 | H40: closed | I40: Planned Work | J40: 3303_Main 1 Sub B C D E F | K40: 202 | M40: sathvik@sobhaconst.com | P40: 2 | Q40: blue | R40: No | V40: Unspecified | X40: Unspecified | Y40: Sub D - Electrical T&C | Z40: Jul 22, 2026 @ 17:53 | AA40: Jul 22, 2026 @ 17:53
...

Sheet SUMMARY
C3: SUMMARY | E3: STAMS : | F3: LPG | G3: ONU | H3: INTERCOM | I3: BOOSTER | J3: SMOKE | K3: SMOKE
F4: C2 | G4: D2 | H4: D4 | I4: D7 | J4: F2 | K4: F3
E5: TOTAL | F5: =COUNTA(STAMP!B2:B356) -> 355 | G5: =COUNTA(STAMP!C2:C356) -> 355 | H5: =COUNTA(STAMP!D2:D356) -> 355 | I5: =COUNTA(STAMP!E2:E356) -> 355 | J5: =COUNTA(STAMP!F2:F356) -> 355 | K5: =COUNTA(STAMP!G2:G356) -> 355
E6: OPEN | F6: =COUNTIF(STAMP!B2:B356,"open") -> 0 | G6: =COUNTIF(STAMP!C2:C356,"open") -> 0 | H6: =COUNTIF(STAMP!D2:D356,"open") -> 0 | I6: =COUNTIF(STAMP!E2:E356,"open") -> 0 | J6: =COUNTIF(STAMP!F2:F356,"open") -> 0 | K6: =COUNTIF(STAMP!G2:G356,"open") -> 0
E7: REVIEW | F7: =COUNTIF(STAMP!B2:B356,"review") -> 0 | G7: =COUNTIF(STAMP!C2:C356,"review") -> 4 | H7: =COUNTIF(STAMP!D2:D356,"review") -> 0 | I7: =COUNTIF(STAMP!E2:E356,"review") -> 0 | J7: =COUNTIF(STAMP!F2:F356,"review") -> 0 | K7: =COUNTIF(STAMP!G2:G356,"review") -> 0
E8: PENDING | F8: =COUNTIF(STAMP!B2:B356,"pending") -> 0 | G8: =COUNTIF(STAMP!C2:C356,"pending") -> 0 | H8: =COUNTIF(STAMP!D2:D356,"pending") -> 0 | I8: =COUNTIF(STAMP!E2:E356,"pending") -> 0 | J8: =COUNTIF(STAMP!F2:F356,"pending") -> 0 | K8: =COUNTIF(STAMP!G2:G356,"pending") -> 0
E9: CLOSED | F9: =COUNTIF(STAMP!B2:B356,"closed") -> 355 | G9: =COUNTIF(STAMP!C2:C356,"closed") -> 351 | H9: =COUNTIF(STAMP!D2:D356,"closed") -> 355 | I9: =COUNTIF(STAMP!E2:E356,"closed") -> 355 | J9: =COUNTIF(STAMP!F2:F356,"closed") -> 355 | K9: =COUNTIF(STAMP!G2:G356,"closed") -> 355
E10: % | F10: =(F8+F9)/F5 -> 1 | G10: =(G8+G9)/G5 -> 0.98873239 | H10: =(H8+H9)/H5 -> 1 | I10: =(I8+I9)/I5 -> 1 | J10: =(J8+J9)/J5 -> 1 | K10: =(K8+K9)/K5 -> 1

Sheet STAMP
A1: FLAT NO | B1: C2 | C1: D2 | D1: D4 | E1: D7 | F1: F2 | G1: F3 | H1: REMARK
A2: 1609 | B2: =_xlfn.XLOOKUP(_xlfn.CONCAT(A2,$B$1),PLANGRID!$A:$A,PLANGRID!$H:$H) -> closed | C2: =_xlfn.XLOOKUP(_xlfn.CONCAT(A2,$C$1),PLANGRID!$A:$A,PLANGRID!$H:$H) -> review | D2: =_xlfn.XLOOKUP(_xlfn.CONCAT(A2,$D$1),PLANGRID!$A:$A,PLANGRID!$H:$H) -> closed | E2: =_xlfn.XLOOKUP(_xlfn.CONCAT(A2,$E$1),PLANGRID!$A:$A,PLANGRID!$H:$H) -> closed | F2: =_xlfn.XLOOKUP(_xlfn.CONCAT(A2,$F$1),PLANGRID!$A:$A,PLANGRID!$H:$H) -> closed | G2: =_xlfn.XLOOKUP(_xlfn.CONCAT(A2,$G$1),PLANGRID!$A:$A,PLANGRID!$H:$H) -> closed | H2: D2 (WIR)
A3: 809_ | B3: =_xlfn.XLOOKUP(_xlfn.CONCAT(A3,$B$1),PLANGRID!$A:$A,PLANGRID!$H:$H) -> closed | C3: =_xlfn.XLOOKUP(_xlfn.CONCAT(A3,$C$1),PLANGRID!$A:$A,PLANGRID!$H:$H) -> review | D3: =_xlfn.XLOOKUP(_xlfn.CONCAT(A3,$D$1),PLANGRID!$A:$A,PLANGRID!$H:$H) -> closed | E3: =_xlfn.XLOOKUP(_xlfn.CONCAT(A3,$E$1),PLANGRID!$A:$A,PLANGRID!$H:$H) -> closed | F3: =_xlfn.XLOOKUP(_xlfn.CONCAT(A3,$F$1),PLANGRID!$A:$A,PLANGRID!$H:$H) -> closed | G3: =_xlfn.XLOOKUP(_xlfn.CONCAT(A3,$G$1),PLANGRID!$A:$A,PLANGRID!$H:$H) -> closed | H3: D2 (WIR)
A4: 1009 | B4: =_xlfn.XLOOKUP(_xlfn.CONCAT(A4,$B$1),PLANGRID!$A:$A,PLANGRID!$H:$H) -> closed | C4: =_xlfn.XLOOKUP(_xlfn.CONCAT(A4,$C$1),PLANGRID!$A:$A,PLANGRID!$H:$H) -> review | D4: =_xlfn.XLOOKUP(_xlfn.CONCAT(A4,$D$1),PLANGRID!$A:$A,PLANGRID!$H:$H) -> closed | E4: =_xlfn.XLOOKUP(_xlfn.CONCAT(A4,$E$1),PLANGRID!$A:$A,PLANGRID!$H:$H) -> closed | F4: =_xlfn.XLOOKUP(_xlfn.CONCAT(A4,$F$1),PLANGRID!$A:$A,PLANGRID!$H:$H) -> closed | G4: =_xlfn.XLOOKUP(_xlfn.CONCAT(A4,$G$1),PLANGRID!$A:$A,PLANGRID!$H:$H) -> closed | H4: D2 (WIR)
A5: 1409 | B5: =_xlfn.XLOOKUP(_xlfn.CONCAT(A5,$B$1),PLANGRID!$A:$A,PLANGRID!$H:$H) -> closed | C5: =_xlfn.XLOOKUP(_xlfn.CONCAT(A5,$C$1),PLANGRID!$A:$A,PLANGRID!$H:$H) -> review | D5: =_xlfn.XLOOKUP(_xlfn.CONCAT(A5,$D$1),PLANGRID!$A:$A,PLANGRID!$H:$H) -> closed | E5: =_xlfn.XLOOKUP(_xlfn.CONCAT(A5,$E$1),PLANGRID!$A:$A,PLANGRID!$H:$H) -> closed | F5: =_xlfn.XLOOKUP(_xlfn.CONCAT(A5,$F$1),PLANGRID!$A:$A,PLANGRID!$H:$H) -> closed | G5: =_xlfn.XLOOKUP(_xlfn.CONCAT(A5,$G$1),PLANGRID!$A:$A,PLANGRID!$H:$H) -> closed | H5: D2 (WIR)
A6: 108_ | B6: =_xlfn.XLOOKUP(_xlfn.CONCAT(A6,$B$1),PLANGRID!$A:$A,PLANGRID!$H:$H) -> closed | C6: =_xlfn.XLOOKUP(_xlfn.CONCAT(A6,$C$1),PLANGRID!$A:$A,PLANGRID!$H:$H) -> closed | D6: =_xlfn.XLOOKUP(_xlfn.CONCAT(A6,$D$1),PLANGRID!$A:$A,PLANGRID!$H:$H) -> closed | E6: =_xlfn.XLOOKUP(_xlfn.CONCAT(A6,$E$1),PLANGRID!$A:$A,PLANGRID!$H:$H) -> closed | F6: =_xlfn.XLOOKUP(_xlfn.CONCAT(A6,$F$1),PLANGRID!$A:$A,PLANGRID!$H:$H) -> closed | G6: =_xlfn.XLOOKUP(_xlfn.CONCAT(A6,$G$1),PLANGRID!$A:$A,PLANGRID!$H:$H) -> closed
A7: 109_ | B7: =_xlfn.XLOOKUP(_xlfn.CONCAT(A7,$B$1),PLANGRID!$A:$A,PLANGRID!$H:$H) -> closed | C7: =_xlfn.XLOOKUP(_xlfn.CONCAT(A7,$C$1),PLANGRID!$A:$A,PLANGRID!$H:$H) -> closed | D7: =_xlfn.XLOOKUP(_xlfn.CONCAT(A7,$D$1),PLANGRID!$A:$A,PLANGRID!$H:$H) -> closed | E7: =_xlfn.XLOOKUP(_xlfn.CONCAT(A7,$E$1),PLANGRID!$A:$A,PLANGRID!$H:$H) -> closed | F7: =_xlfn.XLOOKUP(_xlfn.CONCAT(A7,$F$1),PLANGRID!$A:$A,PLANGRID!$H:$H) -> closed | G7: =_xlfn.XLOOKUP(_xlfn.CONCAT(A7,$G$1),PLANGRID!$A:$A,PLANGRID!$H:$H) -> closed
A8: 110_ | B8: =_xlfn.XLOOKUP(_xlfn.CONCAT(A8,$B$1),PLANGRID!$A:$A,PLANGRID!$H:$H) -> closed | C8: =_xlfn.XLOOKUP(_xlfn.CONCAT(A8,$C$1),PLANGRID!$A:$A,PLANGRID!$H:$H) -> closed | D8: =_xlfn.XLOOKUP(_xlfn.CONCAT(A8,$D$1),PLANGRID!$A:$A,PLANGRID!$H:$H) -> closed | E8: =_xlfn.XLOOKUP(_xlfn.CONCAT(A8,$E$1),PLANGRID!$A:$A,PLANGRID!$H:$H) -> closed | F8: =_xlfn.XLOOKUP(_xlfn.CONCAT(A8,$F$1),PLANGRID!$A:$A,PLANGRID!$H:$H) -> closed | G8: =_xlfn.XLOOKUP(_xlfn.CONCAT(A8,$G$1),PLANGRID!$A:$A,PLANGRID!$H:$H) -> closed
A9: 112_ | B9: =_xlfn.XLOOKUP(_xlfn.CONCAT(A9,$B$1),PLANGRID!$A:$A,PLANGRID!$H:$H) -> closed | C9: =_xlfn.XLOOKUP(_xlfn.CONCAT(A9,$C$1),PLANGRID!$A:$A,PLANGRID!$H:$H) -> closed | D9: =_xlfn.XLOOKUP(_xlfn.CONCAT(A9,$D$1),PLANGRID!$A:$A,PLANGRID!$H:$H) -> closed | E9: =_xlfn.XLOOKUP(_xlfn.CONCAT(A9,$E$1),PLANGRID!$A:$A,PLANGRID!$H:$H) -> closed | F9: =_xlfn.XLOOKUP(_xlfn.CONCAT(A9,$F$1),PLANGRID!$A:$A,PLANGRID!$H:$H) -> closed | G9: =_xlfn.XLOOKUP(_xlfn.CONCAT(A9,$G$1),PLANGRID!$A:$A,PLANGRID!$H:$H) -> closed
A10: 201_ | B10: =_xlfn.XLOOKUP(_xlfn.CONCAT(A10,$B$1),PLANGRID!$A:$A,PLANGRID!$H:$H) -> closed | C10: =_xlfn.XLOOKUP(_xlfn.CONCAT(A10,$C$1),PLANGRID!$A:$A,PLANGRID!$H:$H) -> closed | D10: =_xlfn.XLOOKUP(_xlfn.CONCAT(A10,$D$1),PLANGRID!$A:$A,PLANGRID!$H:$H) -> closed | E10: =_xlfn.XLOOKUP(_xlfn.CONCAT(A10,$E$1),PLANGRID!$A:$A,PLANGRID!$H:$H) -> closed | F10: =_xlfn.XLOOKUP(_xlfn.CONCAT(A10,$F$1),PLANGRID!$A:$A,PLANGRID!$H:$H) -> closed | G10: =_xlfn.XLOOKUP(_xlfn.CONCAT(A10,$G$1),PLANGRID!$A:$A,PLANGRID!$H:$H) -> closed
A11: 202_ | B11: =_xlfn.XLOOKUP(_xlfn.CONCAT(A11,$B$1),PLANGRID!$A:$A,PLANGRID!$H:$H) -> closed | C11: =_xlfn.XLOOKUP(_xlfn.CONCAT(A11,$C$1),PLANGRID!$A:$A,PLANGRID!$H:$H) -> closed | D11: =_xlfn.XLOOKUP(_xlfn.CONCAT(A11,$D$1),PLANGRID!$A:$A,PLANGRID!$H:$H) -> closed | E11: =_xlfn.XLOOKUP(_xlfn.CONCAT(A11,$E$1),PLANGRID!$A:$A,PLANGRID!$H:$H) -> closed | F11: =_xlfn.XLOOKUP(_xlfn.CONCAT(A11,$F$1),PLANGRID!$A:$A,PLANGRID!$H:$H) -> closed | G11: =_xlfn.XLOOKUP(_xlfn.CONCAT(A11,$G$1),PLANGRID!$A:$A,PLANGRID!$H:$H) -> closed
A12: 203_ | B12: =_xlfn.XLOOKUP(_xlfn.CONCAT(A12,$B$1),PLANGRID!$A:$A,PLANGRID!$H:$H) -> closed | C12: =_xlfn.XLOOKUP(_xlfn.CONCAT(A12,$C$1),PLANGRID!$A:$A,PLANGRID!$H:$H) -> closed | D12: =_xlfn.XLOOKUP(_xlfn.CONCAT(A12,$D$1),PLANGRID!$A:$A,PLANGRID!$H:$H) -> closed | E12: =_xlfn.XLOOKUP(_xlfn.CONCAT(A12,$E$1),PLANGRID!$A:$A,PLANGRID!$H:$H) -> closed | F12: =_xlfn.XLOOKUP(_xlfn.CONCAT(A12,$F$1),PLANGRID!$A:$A,PLANGRID!$H:$H) -> closed | G12: =_xlfn.XLOOKUP(_xlfn.CONCAT(A12,$G$1),PLANGRID!$A:$A,PLANGRID!$H:$H) -> closed
A13: 204_ | B13: =_xlfn.XLOOKUP(_xlfn.CONCAT(A13,$B$1),PLANGRID!$A:$A,PLANGRID!$H:$H) -> closed | C13: =_xlfn.XLOOKUP(_xlfn.CONCAT(A13,$C$1),PLANGRID!$A:$A,PLANGRID!$H:$H) -> closed | D13: =_xlfn.XLOOKUP(_xlfn.CONCAT(A13,$D$1),PLANGRID!$A:$A,PLANGRID!$H:$H) -> closed | E13: =_xlfn.XLOOKUP(_xlfn.CONCAT(A13,$E$1),PLANGRID!$A:$A,PLANGRID!$H:$H) -> closed | F13: =_xlfn.XLOOKUP(_xlfn.CONCAT(A13,$F$1),PLANGRID!$A:$A,PLANGRID!$H:$H) -> closed | G13: =_xlfn.XLOOKUP(_xlfn.CONCAT(A13,$G$1),PLANGRID!$A:$A,PLANGRID!$H:$H) -> closed
A14: 205_ | B14: =_xlfn.XLOOKUP(_xlfn.CONCAT(A14,$B$1),PLANGRID!$A:$A,PLANGRID!$H:$H) -> closed | C14: =_xlfn.XLOOKUP(_xlfn.CONCAT(A14,$C$1),PLANGRID!$A:$A,PLANGRID!$H:$H) -> closed | D14: =_xlfn.XLOOKUP(_xlfn.CONCAT(A14,$D$1),PLANGRID!$A:$A,PLANGRID!$H:$H) -> closed | E14: =_xlfn.XLOOKUP(_xlfn.CONCAT(A14,$E$1),PLANGRID!$A:$A,PLANGRID!$H:$H) -> closed | F14: =_xlfn.XLOOKUP(_xlfn.CONCAT(A14,$F$1),PLANGRID!$A:$A,PLANGRID!$H:$H) -> closed | G14: =_xlfn.XLOOKUP(_xlfn.CONCAT(A14,$G$1),PLANGRID!$A:$A,PLANGRID!$H:$H) -> closed
A15: 206_ | B15: =_xlfn.XLOOKUP(_xlfn.CONCAT(A15,$B$1),PLANGRID!$A:$A,PLANGRID!$H:$H) -> closed | C15: =_xlfn.XLOOKUP(_xlfn.CONCAT(A15,$C$1),PLANGRID!$A:$A,PLANGRID!$H:$H) -> closed | D15: =_xlfn.XLOOKUP(_xlfn.CONCAT(A15,$D$1),PLANGRID!$A:$A,PLANGRID!$H:$H) -> closed | E15: =_xlfn.XLOOKUP(_xlfn.CONCAT(A15,$E$1),PLANGRID!$A:$A,PLANGRID!$H:$H) -> closed | F15: =_xlfn.XLOOKUP(_xlfn.CONCAT(A15,$F$1),PLANGRID!$A:$A,PLANGRID!$H:$H) -> closed | G15: =_xlfn.XLOOKUP(_xlfn.CONCAT(A15,$G$1),PLANGRID!$A:$A,PLANGRID!$H:$H) -> closed
A16: 207_ | B16: =_xlfn.XLOOKUP(_xlfn.CONCAT(A16,$B$1),PLANGRID!$A:$A,PLANGRID!$H:$H) -> closed | C16: =_xlfn.XLOOKUP(_xlfn.CONCAT(A16,$C$1),PLANGRID!$A:$A,PLANGRID!$H:$H) -> closed | D16: =_xlfn.XLOOKUP(_xlfn.CONCAT(A16,$D$1),PLANGRID!$A:$A,PLANGRID!$H:$H) -> closed | E16: =_xlfn.XLOOKUP(_xlfn.CONCAT(A16,$E$1),PLANGRID!$A:$A,PLANGRID!$H:$H) -> closed | F16: =_xlfn.XLOOKUP(_xlfn.CONCAT(A16,$F$1),PLANGRID!$A:$A,PLANGRID!$H:$H) -> closed | G16: =_xlfn.XLOOKUP(_xlfn.CONCAT(A16,$G$1),PLANGRID!$A:$A,PLANGRID!$H:$H) -> closed
A17: 111_ | B17: =_xlfn.XLOOKUP(_xlfn.CONCAT(A17,$B$1),PLANGRID!$A:$A,PLANGRID!$H:$H) -> closed | C17: =_xlfn.XLOOKUP(_xlfn.CONCAT(A17,$C$1),PLANGRID!$A:$A,PLANGRID!$H:$H) -> closed | D17: =_xlfn.XLOOKUP(_xlfn.CONCAT(A17,$D$1),PLANGRID!$A:$A,PLANGRID!$H:$H) -> closed | E17: =_xlfn.XLOOKUP(_xlfn.CONCAT(A17,$E$1),PLANGRID!$A:$A,PLANGRID!$H:$H) -> closed | F17: =_xlfn.XLOOKUP(_xlfn.CONCAT(A17,$F$1),PLANGRID!$A:$A,PLANGRID!$H:$H) -> closed | G17: =_xlfn.XLOOKUP(_xlfn.CONCAT(A17,$G$1),PLANGRID!$A:$A,PLANGRID!$H:$H) -> closed
... A94: 909_ | B94: =_xlfn.XLOOKUP(_xlfn.CONCAT(A94,$B$1),PLANGRID!$A:$A,PLANGRID!$H:$H) -> closed | C94: =_xlfn.XLOOKUP(_xlfn.CONCAT(A94,$C$1),PLANGRID!$A:$A,PLANGRID!$H:$H) -> closed | D94: =_xlfn.XLOOKUP(_xlfn.CONCAT(A94,$D$1),PLANGRID!$A:$A,PLANGRID!$H:$H) -> closed | E94: =_xlfn.XLOOKUP(_xlfn.CONCAT(A94,$E$1),PLANGRID!$A:$A,PLANGRID!$H:$H) -> closed | F94: =_xlfn.XLOOKUP(_xlfn.CONCAT(A94,$F$1),PLANGRID!$A:$A,PLANGRID!$H:$H) -> closed | G94: =_xlfn.XLOOKUP(_xlfn.CONCAT(A94,$G$1),PLANGRID!$A:$A,PLANGRID!$H:$H) -> closed
A95: 1001 | B95: =_xlfn.XLOOKUP(_xlfn.CONCAT(A95,$B$1),PLANGRID!$A:$A,PLANGRID!$H:$H) -> closed | C95: =_xlfn.XLOOKUP(_xlfn.CONCAT(A95,$C$1),PLANGRID!$A:$A,PLANGRID!$H:$H) -> closed | D95: =_xlfn.XLOOKUP(_xlfn.CONCAT(A95,$D$1),PLANGRID!$A:$A,PLANGRID!$H:$H) -> closed | E95: =_xlfn.XLOOKUP(_xlfn.CONCAT(A95,$E$1),PLANGRID!$A:$A,PLANGRID!$H:$H) -> closed | F95: =_xlfn.XLOOKUP(_xlfn.CONCAT(A95,$F$1),PLANGRID!$A:$A,PLANGRID!$H:$H) -> closed | G95: =_xlfn.XLOOKUP(_xlfn.CONCAT(A95,$G$1),PLANGRID!$A:$A,PLANGRID!$H:$H) -> closed
A96: 1002 | B96: =_xlfn.XLOOKUP(_xlfn.CONCAT(A96,$B$1),PLANGRID!$A:$A,PLANGRID!$H:$H) -> closed | C96: =_xlfn.XLOOKUP(_xlfn.CONCAT(A96,$C$1),PLANGRID!$A:$A,PLANGRID!$H:$H) -> closed | D96: =_xlfn.XLOOKUP(_xlfn.CONCAT(A96,$D$1),PLANGRID!$A:$A,PLANGRID!$H:$H) -> closed | E96: =_xlfn.XLOOKUP(_xlfn.CONCAT(A96,$E$1),PLANGRID!$A:$A,PLANGRID!$H:$H) -> closed | F96: =_xlfn.XLOOKUP(_xlfn.CONCAT(A96,$F$1),PLANGRID!$A:$A,PLANGRID!$H:$H) -> closed | G96: =_xlfn.XLOOKUP(_xlfn.CONCAT(A96,$G$1),PLANGRID!$A:$A,PLANGRID!$H:$H) -> closed
A97: 1003 | B97: =_xlfn.XLOOKUP(_xlfn.CONCAT(A97,$B$1),PLANGRID!$A:$A,PLANGRID!$H:$H) -> closed | C97: =_xlfn.XLOOKUP(_xlfn.CONCAT(A97,$C$1),PLANGRID!$A:$A,PLANGRID!$H:$H) -> closed | D97: =_xlfn.XLOOKUP(_xlfn.CONCAT(A97,$D$1),PLANGRID!$A:$A,PLANGRID!$H:$H) -> closed | E97: =_xlfn.XLOOKUP(_xlfn.CONCAT(A97,$E$1),PLANGRID!$A:$A,PLANGRID!$H:$H) -> closed | F97: =_xlfn.XLOOKUP(_xlfn.CONCAT(A97,$F$1),PLANGRID!$A:$A,PLANGRID!$H:$H) -> closed | G97: =_xlfn.XLOOKUP(_xlfn.CONCAT(A97,$G$1),PLANGRID!$A:$A,PLANGRID!$H:$H) -> closed
A98: 1004 | B98: =_xlfn.XLOOKUP(_xlfn.CONCAT(A98,$B$1),PLANGRID!$A:$A,PLANGRID!$H:$H) -> closed | C98: =_xlfn.XLOOKUP(_xlfn.CONCAT(A98,$C$1),PLANGRID!$A:$A,PLANGRID!$H:$H) -> closed | D98: =_xlfn.XLOOKUP(_xlfn.CONCAT(A98,$D$1),PLANGRID!$A:$A,PLANGRID!$H:$H) -> closed | E98: =_xlfn.XLOOKUP(_xlfn.CONCAT(A98,$E$1),PLANGRID!$A:$A,PLANGRID!$H:$H) -> closed | F98: =_xlfn.XLOOKUP(_xlfn.CONCAT(A98,$F$1),PLANGRID!$A:$A,PLANGRID!$H:$H) -> closed | G98: =_xlfn.XLOOKUP(_xlfn.CONCAT(A98,$G$1),PLANGRID!$A:$A,PLANGRID!$H:$H) -> closed
A99: 1005 | B99: =_xlfn.XLOOKUP(_xlfn.CONCAT(A99,$B$1),PLANGRID!$A:$A,PLANGRID!$H:$H) -> closed | C99: =_xlfn.XLOOKUP(_xlfn.CONCAT(A99,$C$1),PLANGRID!$A:$A,PLANGRID!$H:$H) -> closed | D99: =_xlfn.XLOOKUP(_xlfn.CONCAT(A99,$D$1),PLANGRID!$A:$A,PLANGRID!$H:$H) -> closed | E99: =_xlfn.XLOOKUP(_xlfn.CONCAT(A99,$E$1),PLANGRID!$A:$A,PLANGRID!$H:$H) -> closed | F99: =_xlfn.XLOOKUP(_xlfn.CONCAT(A99,$F$1),PLANGRID!$A:$A,PLANGRID!$H:$H) -> closed | G99: =_xlfn.XLOOKUP(_xlfn.CONCAT(A99,$G$1),PLANGRID!$A:$A,PLANGRID!$H:$H) -> closed
A100: 1006 | B100: =_xlfn.XLOOKUP(_xlfn.CONCAT(A100,$B$1),PLANGRID!$A:$A,PLANGRID!$H:$H) -> closed | C100: =_xlfn.XLOOKUP(_xlfn.CONCAT(A100,$C$1),PLANGRID!$A:$A,PLANGRID!$H:$H) -> closed | D100: =_xlfn.XLOOKUP(_xlfn.CONCAT(A100,$D$1),PLANGRID!$A:$A,PLANGRID!$H:$H) -> closed | E100: =_xlfn.XLOOKUP(_xlfn.CONCAT(A100,$E$1),PLANGRID!$A:$A,PLANGRID!$H:$H) -> closed | F100: =_xlfn.XLOOKUP(_xlfn.CONCAT(A100,$F$1),PLANGRID!$A:$A,PLANGRID!$H:$H) -> closed | G100: =_xlfn.XLOOKUP(_xlfn.CONCAT(A100,$G$1),PLANGRID!$A:$A,PLANGRID!$H:$H) -> closed
A101: 1007 | B101: =_xlfn.XLOOKUP(_xlfn.CONCAT(A101,$B$1),PLANGRID!$A:$A,PLANGRID!$H:$H) -> closed | C101: =_xlfn.XLOOKUP(_xlfn.CONCAT(A101,$C$1),PLANGRID!$A:$A,PLANGRID!$H:$H) -> closed | D101: =_xlfn.XLOOKUP(_xlfn.CONCAT(A101,$D$1),PLANGRID!$A:$A,PLANGRID!$H:$H) -> closed | E101: =_xlfn.XLOOKUP(_xlfn.CONCAT(A101,$E$1),PLANGRID!$A:$A,PLANGRID!$H:$H) -> closed | F101: =_xlfn.XLOOKUP(_xlfn.CONCAT(A101,$F$1),PLANGRID!$A:$A,PLANGRID!$H:$H) -> closed | G101: =_xlfn.XLOOKUP(_xlfn.CONCAT(A101,$G$1),PLANGRID!$A:$A,PLANGRID!$H:$H) -> closed
A102: 1008 | B102: =_xlfn.XLOOKUP(_xlfn.CONCAT(A102,$B$1),PLANGRID!$A:$A,PLANGRID!$H:$H) -> closed | C102: =_xlfn.XLOOKUP(_xlfn.CONCAT(A102,$C$1),PLANGRID!$A:$A,PLANGRID!$H:$H) -> closed | D102: =_xlfn.XLOOKUP(_xlfn.CONCAT(A102,$D$1),PLANGRID!$A:$A,PLANGRID!$H:$H) -> closed | E102: =_xlfn.XLOOKUP(_xlfn.CONCAT(A102,$E$1),PLANGRID!$A:$A,PLANGRID!$H:$H) -> closed | F102: =_xlfn.XLOOKUP(_xlfn.CONCAT(A102,$F$1),PLANGRID!$A:$A,PLANGRID!$H:$H) -> closed | G102: =_xlfn.XLOOKUP(_xlfn.CONCAT(A102,$G$1),PLANGRID!$A:$A,PLANGRID!$H:$H) -> closed
A103: 1010 | B103: =_xlfn.XLOOKUP(_xlfn.CONCAT(A103,$B$1),PLANGRID!$A:$A,PLANGRID!$H:$H) -> closed | C103: =_xlfn.XLOOKUP(_xlfn.CONCAT(A103,$C$1),PLANGRID!$A:$A,PLANGRID!$H:$H) -> closed | D103: =_xlfn.XLOOKUP(_xlfn.CONCAT(A103,$D$1),PLANGRID!$A:$A,PLANGRID!$H:$H) -> closed | E103: =_xlfn.XLOOKUP(_xlfn.CONCAT(A103,$E$1),PLANGRID!$A:$A,PLANGRID!$H:$H) -> closed | F103: =_xlfn.XLOOKUP(_xlfn.CONCAT(A103,$F$1),PLANGRID!$A:$A,PLANGRID!$H:$H) -> closed | G103: =_xlfn.XLOOKUP(_xlfn.CONCAT(A103,$G$1),PLANGRID!$A:$A,PLANGRID!$H:$H) -> closed
A104: 1101 | B104: =_xlfn.XLOOKUP(_xlfn.CONCAT(A104,$B$1),PLANGRID!$A:$A,PLANGRID!$H:$H) -> closed | C104: =_xlfn.XLOOKUP(_xlfn.CONCAT(A104,$C$1),PLANGRID!$A:$A,PLANGRID!$H:$H) -> closed | D104: =_xlfn.XLOOKUP(_xlfn.CONCAT(A104,$D$1),PLANGRID!$A:$A,PLANGRID!$H:$H) -> closed | E104: =_xlfn.XLOOKUP(_xlfn.CONCAT(A104,$E$1),PLANGRID!$A:$A,PLANGRID!$H:$H) -> closed | F104: =_xlfn.XLOOKUP(_xlfn.CONCAT(A104,$F$1),PLANGRID!$A:$A,PLANGRID!$H:$H) -> closed | G104: =_xlfn.XLOOKUP(_xlfn.CONCAT(A104,$G$1),PLANGRID!$A:$A,PLANGRID!$H:$H) -> closed
A105: 1102 | B105: =_xlfn.XLOOKUP(_xlfn.CONCAT(A105,$B$1),PLANGRID!$A:$A,PLANGRID!$H:$H) -> closed | C105: =_xlfn.XLOOKUP(_xlfn.CONCAT(A105,$C$1),PLANGRID!$A:$A,PLANGRID!$H:$H) -> closed | D105: =_xlfn.XLOOKUP(_xlfn.CONCAT(A105,$D$1),PLANGRID!$A:$A,PLANGRID!$H:$H) -> closed | E105: =_xlfn.XLOOKUP(_xlfn.CONCAT(A105,$E$1),PLANGRID!$A:$A,PLANGRID!$H:$H) -> closed | F105: =_xlfn.XLOOKUP(_xlfn.CONCAT(A105,$F$1),PLANGRID!$A:$A,PLANGRID!$H:$H) -> closed | G105: =_xlfn.XLOOKUP(_xlfn.CONCAT(A105,$G$1),PLANGRID!$A:$A,PLANGRID!$H:$H) -> closed
A106: 1103 | B106: =_xlfn.XLOOKUP(_xlfn.CONCAT(A106,$B$1),PLANGRID!$A:$A,PLANGRID!$H:$H) -> closed | C106: =_xlfn.XLOOKUP(_xlfn.CONCAT(A106,$C$1),PLANGRID!$A:$A,PLANGRID!$H:$H) -> closed | D106: =_xlfn.XLOOKUP(_xlfn.CONCAT(A106,$D$1),PLANGRID!$A:$A,PLANGRID!$H:$H) -> closed | E106: =_xlfn.XLOOKUP(_xlfn.CONCAT(A106,$E$1),PLANGRID!$A:$A,PLANGRID!$H:$H) -> closed | F106: =_xlfn.XLOOKUP(_xlfn.CONCAT(A106,$F$1),PLANGRID!$A:$A,PLANGRID!$H:$H) -> closed | G106: =_xlfn.XLOOKUP(_xlfn.CONCAT(A106,$G$1),PLANGRID!$A:$A,PLANGRID!$H:$H) -> closed
... A356: 3709 | B356: =_xlfn.XLOOKUP(_xlfn.CONCAT(A356,$B$1),PLANGRID!$A:$A,PLANGRID!$H:$H) -> closed | C356: =_xlfn.XLOOKUP(_xlfn.CONCAT(A356,$C$1),PLANGRID!$A:$A,PLANGRID!$H:$H) -> closed | D356: =_xlfn.XLOOKUP(_xlfn.CONCAT(A356,$D$1),PLANGRID!$A:$A,PLANGRID!$H:$H) -> closed | E356: =_xlfn.XLOOKUP(_xlfn.CONCAT(A356,$E$1),PLANGRID!$A:$A,PLANGRID!$H:$H) -> closed | F356: =_xlfn.XLOOKUP(_xlfn.CONCAT(A356,$F$1),PLANGRID!$A:$A,PLANGRID!$H:$H) -> closed | G356: =_xlfn.XLOOKUP(_xlfn.CONCAT(A356,$G$1),PLANGRID!$A:$A,PLANGRID!$H:$H) -> closed

Sheet ELV WIRS
A1: WIR Ref. No. | B1: # ID | C1: Level/ Apartment | D1: Description | E1: PlanGrid Link | F1: STUTES | G1: CONSULTANT COMMENT | H1: REV - 01
A3: WIR-WAO-EL-2957 | B3: #2495 | C3: Level 7,8,9,10 | D3: Witnessing of T&C of Cat 6 Cables for Structured Cabling System as per the attached drawing and Test reports. (FLUKE TEST) Apartment’s 705,706,805,905,1005 | E3: PlanGrid | F3: APROVED
A4: WIR-WAO-EL-2960 | B4: #2508 | C4: Level 29 | D4: Inspection of LPG Gas detector & FAS integration testing of the following apartments. 2901,2902,2903,2904,2905,2906,2907,2908,2909. | E4: PlanGrid | F4: APROVED
A5: WIR-WAO-EL-2961 | B5: #2509 | C5: Level 30 | D5: Inspection of LPG Gas detector & FAS integration testing of the following apartments. 3001,3002,3003,3004,3005,3006,3007,3008,3009,3010. | E5: PlanGrid | F5: APROVED
A6: WIR-WAO-EL-2962 | B6: #2510 | C6: Level 31 | D6: Inspection of LPG Gas detector & FAS integration testing of the following apartments. 3101,3102,3103,3104,3105,3106,3107,3108,3109. | E6: PlanGrid | F6: APROVED
A7: WIR-WAO-EL-2963 | B7: #2511 | C7: Level 32 | D7: Inspection of LPG Gas detector & FAS integration testing of the following apartments. 3201,3202,3203,3204,3205,3206,3207,3208,3209,3210. | E7: PlanGrid | F7: APROVED
A8: WIR-WAO-EL-2964 | B8: #2512 | C8: Level 29 | D8: Witnessing of T&C of Cat 6 Cables for Structured Cabling System as per the attached drawing and Test reports. (FLUKE TEST) Apartments 2903,2904,2905,2906,2907,2908,2909. | E8: PlanGrid | F8: APROVED
A9: WIR-WAO-EL-2965 | B9: #2513 | C9: Level 30 | D9: Inspection request for witnessing for functionality of video intercom. As per the attached Schematic drawing & Test reports. Apartments 3001,3002,3003,3004,3005,3006,3007,3009,3009,3010. | E9: PlanGrid | F9: APROVED
A10: WIR-WAO-EL-2966 | B10: #2514 | C10: Level 29 | D10: Inspection request for witnessing for functionality of video intercom. As per the attached Schematic drawing & Test reports. Apartments 2901,2902,2903,2904,2905,2906,2907,2908,2909,2909. | E10: PlanGrid | F10: APROVED
A11: WIR-WAO-EL-2967 | B11: #2516 | C11: Level 30 | D11: Witnessing of T&C of Cat 6 Cables for Structured Cabling System as per the attached drawing and Test reports. (FLUKE TEST) Apartments 3001,3002,3003,3004,3005,3006,3007,3008,3009,3009,3010. | E11: PlanGrid | F11: APROVED
A12: WIR-WAO-EL-2976 | B12: #2587 | C12: Level 20 | D12: Inspection request for witnessing for functionality of video intercom. As per the attached Schematic drawing & Test reports. Apartments 2001,2002,2003,2005,2006,2007,2008,2009,2010. | E12: PlanGrid | F12: APROVED
A13: WIR-WAO-EL-2977 | B13: #2588 | C13: Level 31 | D13: Inspection request for witnessing for functionality of video intercom. As per the attached Schematic drawing & Test reports. Apartments 3101,3102,3103,3104,3105,3106,3107,3108,3109,3109. | E13: PlanGrid | F13: APROVED
A14: WIR-WAO-EL-2978 | B14: #2589 | C14: Level 20 | D14: Witnessing of T&C of Cat 6 Cables for Structured Cabling System as per the attached drawing and Test reports. (FLUKE TEST) Apartments 2001,2002,2003,2005,2006,2007,2008,2009. | E14: PlanGrid | F14: APROVED
... A41: WIR-WAO-EL-3028 | B41: #2738 | C41: Level 36 | D41: Inspection request for witnessing for functionality of video intercom. As per the attached Schematic drawing & Test reports. Apartments. 3601,3602,3603,3604,3605,3606,3607,3608,3609. | E41: PlanGrid | F41: APROVED
A42: WIR-WAO-EL-3035 | B42: #2762 | C42: All Level | D42: Witnessing of Final Testing and Commission of Fire Alarm System as per the attached reports. | E42: PlanGrid | F42: NOT APROVED | G42: Site not ready for inspection | H42: APROVED
A43: WIR-WAO-EL-3039 | B43: #2784 | C43: Level 05 | D43: Witnessing of T&C of Cat 6 Cables for Structured Cabling System as per the attached drawing and Test reports. (FLUKE TEST) Apartments. 501,502,506,507. | E43: PlanGrid | F43: APROVED
A44: WIR-WAO-EL-3040 | B44: #2799 | C44: Level 05 | D44: Inspection request for witnessing for functionality of video intercom. As per the attached Schematic drawing & Test reports. Apartments. 501,502,503,504,505,506,507,508,509,510,511,512. | E44: PlanGrid | F44: REJECT | G44: Site not ready for inspection | H44: APROVED
A45: WIR-WAO-EL-3041 | B45: #2813 | C45: Level 36 | D45: Inspection request for witnessing for functionality of video intercom. As per the attached Schematic drawing & Test reports. Apartment. 3610. | E45: PlanGrid | F45: APROVED
A46: WIR-WAO-EL-3042 | B46: #2814 | C46: Level 05 | D46: Inspection of LPG Gas detector & FAS integration testing of the following apartments. 508,509,510,511,512. TB | E46: PlanGrid | F46: REJECT
A47: WIR-WAO-EL-3043 | B47: #2815 | C47: Level 01 | D47: Inspection request for witnessing for functionality of video intercom. As per the attached Schematic drawing & Test reports. Apartments 108,109,110,111,112. | E47: PlanGrid | F47: APROVED
A48: WIR-WAO-EL-3044 | B48: #2816 | C48: Level 01 | D48: Inspection of LPG Gas detector & FAS integration testing of the following apartments. 108,109,110,111,112.TB | E48: PlanGrid | F48: APROVED
A49: WIR-WAO-EL-3045 | B49: #2817 | C49: Level 03 | D49: Inspection request for witnessing for functionality of video intercom. As per the attached Schematic drawing & Test reports. Apartments 301,302,303,304,305,306,307,308,309,310,311,312. | E49: PlanGrid | F49: APROVED
A50: WIR-WAO-EL-3047 | B50: #2834 | C50: Level 05 | D50: Witnessing of T&C of Cat 6 Cables for Structured Cabling System as per the attached drawing and Test reports. (FLUKE TEST) Apartments. 503,504,505,508,509,510,511,512. | E50: PlanGrid | F50: APROVED
A51: WIR-WAO-EL-3048 | B51: #2843 | C51: Level 03 | D51: Inspection of LPG Gas detector & FAS integration testing of the following apartments. 301,302,303,304,305,306,307,308,309,310,311,312. TA & TB | E51: PlanGrid | F51: APROVED
A52: WIR-WAO-EL-3049 | B52: #2844 | C52: Level 02 | D52: Inspection of LPG Gas detector & FAS integration testing of the following apartments. 201,202,203,204,205,206,207,208,209,210,211,212. TA & TB | E52: PlanGrid | F52: APROVED
A53: WIR-WAO-EL-3051 | B53: #2849 | C53: Level 6 | D53: Witnessing of T&C of Cat 6 Cables for Structured Cabling System as per the attached drawing and Test reports. (FLUKE TEST) Apartments 605,607 | E53: PlanGrid | F53: APROVED
A54: WIR-WAO-EL-3064 | B54: #2917 | C54: Level 3 | D54: Witnessing of T&C of Cat 6 Cables for Structured Cabling System as per the attached drawing and Test reports. (FLUKE TEST) Apartments. 301,302,303,304,305,306,307,308,309,310,311,312. | E54: PlanGrid | F54: IN PROCESS
A55: WIR-WAO-EL-3065 | B55: #65 | C55: All Level | D55: Installation of Witnessing for the Testing & commission for INTERCOM. TA & TB -ALL FLOORS As per the attached schematic drawing and checklist, Test report. | E55: PlanGrid | F55: IN PROCESS

Sheet DRAFT
A12: wir | B12: id | C12: lev | D12: de | E12: li
A13: WIR-WAO-EL-3027 | B13: #2727 | C13: Level 02 | D13: Inspection request for witnessing for functionality of video intercom. As per the attached Schematic drawing & Test reports. Apartments. 201,202,203,204,205,206,207,208,209,210,211,212. | E13: PlanGrid
A14: WIR-WAO-EL-3039 | B14: #2784 | C14: Level 05 | D14: Witnessing of T&C of Cat 6 Cables for Structured Cabling System as per the attached drawing and Test reports. (FLUKE TEST) Apartments. 501,502,506,507. | E14: PlanGrid
A15: WIR-WAO-EL-3025 | B15: #2725 | C15: Level 36 | D15: Witnessing of T&C of Cat 6 Cables for Structured Cabling System as per the attached drawing and Test reports. (FLUKE TEST) Apartments. 3601,3602,3603,3604,3605,3606,3607,3608,3609,3610. | E15: PlanGrid
A16: WIR-WAO-EL-3028 | B16: #2738 | C16: Level 36 | D16: Inspection request for witnessing for functionality of video intercom. As per the attached Schematic drawing & Test reports. Apartments. 3601,3602,3603,3604,3605,3606,3607,3608,3609. | E16: PlanGrid
A17: WIR-WAO-EL-3026 | B17: #2726 | C17: Level 37 | D17: Witnessing of T&C of Cat 6 Cables for Structured Cabling System as per the attached drawing and Test reports. (FLUKE TEST) Apartments. 3701,3702,3703,3704,3705,3706,3707,3708,3709. | E17: PlanGrid
A18: WIR-WAO-EL-3023 | B18: #2723 | C18: Level 37 | D18: Inspection of LPG Gas detector & FAS integration testing of the following apartments. 3701,3702,3703,3704,3705,3706,3707,3708,3709. | E18: PlanGrid
A19: WIR-WAO-EL-3024 | B19: #2724 | C19: Level 37 | D19: Inspection request for witnessing for functionality of video intercom. As per the attached Schematic drawing & Test reports. Apartments 3701,3702,3703,3704,3705,3706,3707,3708,3709. | E19: PlanGrid
A23: wir | B23: id | C23: lev | D23: de | E23: li
A24: WIR-WAO-EL-3040 | B24: #2799 | C24: Level 05 | D24: Inspection request for witnessing for functionality of video intercom. As per the attached Schematic drawing & Test reports. Apartments. 501,502,503,504,505,506,507,508,509,510,511,512. | E24: PlanGrid
A25: WIR-WAO-EL-3041 | B25: #2813 | C25: Level 36 | D25: Inspection request for witnessing for functionality of video intercom. As per the attached Schematic drawing & Test reports. Apartment. 3610. | E25: PlanGrid
A26: WIR-WAO-EL-3042 | B26: #2814 | C26: Level 05 | D26: Inspection of LPG Gas detector & FAS integration testing of the following apartments. 508,509,510,511,512. | E26: PlanGrid
... A46: WIR-WAO-EL-3096 | B46: #105 | C46: All Levels | D46: Inspection request for Witnessing of T&C of Lighting and Control system as per shop drawings. | E46: PlanGrid

Sheet INFORMETION
A1: STAMP INFORMATION FOR ELV
A2: SHEET NAME | B2: STAMP | C2: DOCUMENT | D2: COMMENTS
A3: (3FIN | B3: Q1 BOOSTER (GSM) | D3: Manuel Rebera : Antenna installation competed. Activation will be done by DU RFS Team after the BCC handing over.
A4: (3FIN | B4: Q3 BOOSTER (GSM) | D4: Manuel Rebera : Antenna installation competed. Activation will be done by DU RFS Team after the BCC handing over.
A5: (6T&C - UNIT AREA | B5: C2 LPG | D5: LPG functionality kitchen detector and solenoid valve functionality test completed with fire alarm integration. Approved WIR and photos attached for
A6: (6T&C - UNIT AREA | B6: D2 ONU DATA | D6: Fluke Test for Cat 6 cable work is completed, approved WIR copy attached for reference.
A7: (6T&C - UNIT AREA | B7: D4 INTERCOM | D7: Intercom T&C Completed, WIR attached for reference.
A8: (6T&C - UNIT AREA | B8: D7 BOOSTER (GSM) | D8: Manuel Rebera : GSM- Antenna and cable installation completed. Completed GSM cable pulling as per the Du design drawing and T&C will be done as a system completely one time in coordination with GSM service provider Du.
A9: (6T&C - UNIT AREA | B9: F2 FIRE ALARM | D9: FAS loop test was completed and approved WIR has been attached for reference.
A10: (6T&C - UNIT AREA | B10: F3 FIRE ALARM | D10: FAS loop test was completed and approved WIR has been attached for reference.
A11: NOTE : Please ignore the previous comment.
A12: (6T&C - COMMON AREA | B12: J3 BOOSTER (GSM) | D12: Manuel Rebera : GSM- Antenna and cable installation completed. Completed GSM cable pulling as per the Du design drawing and T&C will be done as a system completely one time in coordination with GSM service provider Du.
A13: (6T&C - COMMON AREA | B13: K2 FIRE ALARM | D13: FAS loop test was completed and approved WIR has been attached for reference.
A14: (6T&C - COMMON AREA | B14: K3 FIRE ALARM | D14: FAS loop test was completed and approved WIR has been attached for reference.
A15: (6T&C - Specialist system | B15: FIRE ALARM
B16: CBS
B17: ACS
A21: T&C - WIR INFORMATIONS
A22: STAMP & Description | B22: ATTACHMENT | C22: STAMP & Description | D22: ATTACHMENT
A23: ( C2 LPG) - Inspection of LPG Gas detector & FAS integration testing of the following apartments. 108,109,110,111,112. | B23: Cable pulling WIR | C23: (D4 INTERCOM ) - Witnessing of T&C of Cat 6 Cables for Structured Cabling System as per the attached drawing and Test reports. (FLUKE TEST) Apartments. 201,202,203,204,205,206,207,208,209 | D23: Cable pulling WIR
B24: Checklist | D24: Checklist
B25: Schematic | D25: Intercom Schematic
B26: PANEL photos | D26: Device Certificate
B27: Device photos | D27: Intercom IP Details
A28: (D2 ONU DATA)-Inspection request for Witnessing of T&C of Cat 6 Cables for Structured Cabling System as per the attached drawing and Test reports. (FLUKE TEST) Apartments 1401,1402,1403,1404,. | B28: Checklist | C28: ( F2 FIRE ALARM) - Inspection request for the witnessing of Fire Alarm loop test (FACP-01)- Loop 1, Loop 2, Loop 3, Loop 4, Level 8 to Level 14 as per attached drawing. | D28: DATA SHEET REPORT
B29: Device Certificate | D29: Cable pulling WIR
B30: Telecom SCHEMATIC | D30: Device photos
B31: SHOP DRAWING | D31: Checklist
D32: Schematic
D33: SHOP DRAWING
A35: FINAL ELV -INSPECTION WIR DOCUMENTS AND STAMPS
A36: SHEET NAME | B36: SYSTEM | C36: Description
A37: (6T&C - Specialist system | B37: ACS | C37: Installation of Witnessing for the Testing & commission for Access control system. TA & TB GF to Level 6 As per the attached schematic drawing and checklist, Test report. | D37: PHOTOS, SCHEMATIC- DRAWING,CHECKLIST , METHOD OF STATEMENTS, SUBMITTALS,SHOP DRAWING WITH LEVEL , IP ADDRESS EXCEL SHEETS,
A38: (6T&C - Specialist system | B38: INTERCOM | C38: Installation of Witnessing for the Testing & commission for INTERCOM. TA & TB -ALL FLOORS As per the attached schematic drawing and checklist, Test report. | D38: PHOTOS, SCHEMATIC- DRAWING,CHECKLIST , METHOD OF STATEMENTS, SUBMITTALS,SHOP DRAWING WITH LEVEL , IP ADDRESS EXCEL SHEETS,
A39: (6T&C - Specialist system | B39: CBS | C39: Inspection request for Witnessing of Central battery system as per attached shop drawings and Lux report. | D39: PHOTOS, SCHEMATIC- DRAWING,CHECKLIST , METHOD OF STATEMENTS, SUBMITTALS,SHOP DRAWING WITH LEVEL , LUX EXCEL SHEETS REPORT,
A40: (6T&C - Specialist system | B40: FIRE ALARM
A41: (6T&C - Specialist system | B41: BGM
A42: (6T&C - Specialist system | B42: CCTV
A43: (6T&C - Specialist system | B43: LCP PROGRAMING

Sheet BASS

Sheet MANPOWER 
A1: ELV MANPOWER LIST
A2: S.N. | B2: EMP NO | C2: NAME | D2: D.O.J | E2: TRADE | F2: TR | G2: remark
A3: 1 | B3: C31241 | C3: Harikesh Yadav Ramdayal Yadav | D3: 45427 | E3: Electrician | F3: JEBAL ALI -03 | G3: Fire Alarm Trouble Shooting
A4: 2 | B4: C31847 | C4: MD Tavish MD Afjal | D4: 45439 | E4: Electrician | F4: JEBAL ALI -01 | G4: Fire Alarm Trouble Shooting
A5: 3 | B5: C32063 | C5: Nijamuddin Zamil Khan | D5: 45448 | E5: Electrician | F5: JEBAL ALI -01 | G5: CBS Trouble Shooting
A6: 4 | B6: C31233 | C6: Santosh Kumar Baliram | D6: 45427 | E6: Electrician | F6: JEBAL ALI -03 | G6: CBS Trouble Shooting
A7: 5 | B7: C60216 | C7: Sudhakar Rajbhar Uday Raj Rajbhar | D7: 45660 | E7: Electrician | F7: DIP -01 | G7: KeepOut Apt & Corridor
A8: 6 | B8: C21801 | C8: Md Arif Md Ali | D8: 45262 | E8: Electrician | F8: Al Ruwayyah | G8: KeepOut Apt & Corridor
A9: 7 | B9: C26806 | C9: Diwakar Verma | D9: 45262 | E9: Electrician- CH | F9: AL Quoz | G9: Plangrid & site work

Sheet FAS RESPONSE
B1: CONSULTANT COMMENTS | C1: REPLY TO COMMENTS
A2: 1 | B2: Functionality of doors shall be rechecked (Refer video) | C2: Done. | G2: Completed.
A3: 2 | B3: Shall be coordinated with civil for door closure as some doors not closing | C3: Noted.
A4: 3 | B4: Amenity areas lock termination shall be done properly | C4: Noted | G4: Noted
A5: 4 | B5: As agreed earlier, outdoor IP rated device not installed | C5: Done.
G6: Atteched
G8: Done
